<?xml version="1.0"?>

<robot name="robot_arm">
  <!-- Link 1 -->
  <link name="base_link">
    <visual>
      <geometry>
        <box size="0.1 0.1 0.1"/>
      </geometry>
    </visual>
  </link>

  <!-- Link 2 -->
  <link name="link1">
    <visual>
      <geometry>
        <cylinder length="0.4" radius="0.05"/>
      </geometry>
    </visual>
    <collision>
      <geometry>
        <cylinder length="0.4" radius="0.05"/>
      </geometry>
    </collision>
  </link>

  <!-- Link 3 -->
  <link name="link2">
    <visual>
      <geometry>
        <box size="0.1 0.1 0.1"/>
      </geometry>
    </visual>
    <collision>
      <geometry>
        <box size="0.1 0.1 0.1"/>
      </geometry>
    </collision>
  </link>

  <!-- Link 4 (end effector) -->
  <link name="end_effector">
    <visual>
      <geometry>
        <sphere radius="0.05"/>
      </geometry>
    </visual>
    <collision>
      <geometry>
        <sphere radius="0.05"/>
      </geometry>
    </collision>
  </link>

  <!-- Joints -->
  <joint name="joint1" type="revolute">
    <parent link="base_link"/>
    <child link="link1"/>
    <origin xyz="0 0 0.2" rpy="0 0 0"/>
    <axis xyz="0 0 1"/>
    <limit lower="-1.57" upper="1.57"/>
  </joint>

  <joint name="joint2" type="revolute">
    <parent link="link1"/>
    <child link="link2"/>
    <origin xyz="0 0 0.4" rpy="0 0 0"/>
    <axis xyz="0 1 0"/>
    <limit lower="-1.57" upper="1.57"/>
  </joint>

  <joint name="joint3" type="revolute">
    <parent link="link2"/>
    <child link="end_effector"/>
    <origin xyz="0 0 0.4" rpy="0 0 0"/>
    <axis xyz="0 0 1"/>
    <limit lower="-1.57" upper="1.57"/>
  </joint>
</robot>
