<?xml version="1.0" ?>
<!-- =================================================================================== -->
<!-- |    This document was autogenerated by xacro from /home/ethan/Projects/Rover/src/uirover_description/urdf/physical.urdf.xacro | -->
<!-- |    EDITING THIS FILE BY HAND IS NOT RECOMMENDED                                 | -->
<!-- =================================================================================== -->
<robot name="uiowa_rover">
  <!-- XACRO CONSTANTS -->
  <!-- <xacro:property name="pi" value="3.14159265359" /> -->
  <!-- XACRO MACROS -->
  <!-- ROBOT DESCRIPTION -->
  <link name="base_link">
  </link>
  <!-- CHASSIS -->
  <link name="chassis">
    <visual>
      <geometry>
        <box size="0.45 0.45 0.3"/>
      </geometry>
      <material name="Grey">
        <color rgba="0.7 0.7 0.7 1.0"/>
      </material>
    </visual>
    <visual>
      <origin rpy="0 0 0" xyz="0.375 0 -0.125"/>
      <geometry>
        <box size="0.3 0.45 0.05"/>
      </geometry>
      <material name="Grey">
        <color rgba="0.7 0.7 0.7 1.0"/>
      </material>
    </visual>
    <collision>
      <geometry>
        <box size="0.45 0.45 0.3"/>
      </geometry>
    </collision>
    <collision>
      <origin rpy="0 0 0" xyz="0.375 0 -0.125"/>
      <geometry>
        <box size="0.3 0.45 0.05"/>
      </geometry>
    </collision>
    <inertial>
      <mass value="5"/>
      <inertia ixx="0.12187499999999998" ixy="0.0" ixz="0.0" iyy="0.12187499999999998" iyz="0.0" izz="0.16874999999999998"/>
    </inertial>
  </link>
  <joint name="chasiss_joint" type="fixed">
    <parent link="base_link"/>
    <child link="chassis"/>
    <origin rpy="0 0 0" xyz="0 0 0"/>
  </joint>
  <link name="front_l_wheel">
    <visual>
      <geometry>
        <cylinder length="0.1" radius="0.114"/>
      </geometry>
      <material name="Grey">
        <color rgba="0.7 0.7 0.7 1.0"/>
      </material>
    </visual>
    <collision>
      <geometry>
        <cylinder length="0.1" radius="0.114"/>
      </geometry>
    </collision>
    <inertial>
      <mass value="0.5"/>
      <inertia ixx="0.002041166666666667" ixy="0.0" ixz="0.0" iyy="0.002041166666666667" iyz="0.0" izz="0.003249"/>
    </inertial>
  </link>
  <joint name="front_l_wheel_joint" type="continuous">
    <parent link="chassis"/>
    <child link="front_l_wheel"/>
    <origin rpy="1.5707963267948966 0 0" xyz="0.5800000000000001 0.4 -0.35"/>
    <axis xyz="0 0 1"/>
  </joint>
  <link name="front_r_wheel">
    <visual>
      <geometry>
        <cylinder length="0.1" radius="0.114"/>
      </geometry>
      <material name="Grey">
        <color rgba="0.7 0.7 0.7 1.0"/>
      </material>
    </visual>
    <collision>
      <geometry>
        <cylinder length="0.1" radius="0.114"/>
      </geometry>
    </collision>
    <inertial>
      <mass value="0.5"/>
      <inertia ixx="0.002041166666666667" ixy="0.0" ixz="0.0" iyy="0.002041166666666667" iyz="0.0" izz="0.003249"/>
    </inertial>
  </link>
  <joint name="front_r_wheel_joint" type="continuous">
    <parent link="chassis"/>
    <child link="front_r_wheel"/>
    <origin rpy="1.5707963267948966 0 0" xyz="0.5800000000000001 -0.4 -0.35"/>
    <axis xyz="0 0 1"/>
  </joint>
  <link name="mid_l_wheel">
    <visual>
      <geometry>
        <cylinder length="0.1" radius="0.114"/>
      </geometry>
      <material name="Grey">
        <color rgba="0.7 0.7 0.7 1.0"/>
      </material>
    </visual>
    <collision>
      <geometry>
        <cylinder length="0.1" radius="0.114"/>
      </geometry>
    </collision>
    <inertial>
      <mass value="0.5"/>
      <inertia ixx="0.002041166666666667" ixy="0.0" ixz="0.0" iyy="0.002041166666666667" iyz="0.0" izz="0.003249"/>
    </inertial>
  </link>
  <joint name="mid_l_wheel_joint" type="continuous">
    <parent link="chassis"/>
    <child link="mid_l_wheel"/>
    <origin rpy="1.5707963267948966 0 0" xyz="0.18 0.4 -0.35"/>
    <axis xyz="0 0 1"/>
  </joint>
  <link name="mid_r_wheel">
    <visual>
      <geometry>
        <cylinder length="0.1" radius="0.114"/>
      </geometry>
      <material name="Grey">
        <color rgba="0.7 0.7 0.7 1.0"/>
      </material>
    </visual>
    <collision>
      <geometry>
        <cylinder length="0.1" radius="0.114"/>
      </geometry>
    </collision>
    <inertial>
      <mass value="0.5"/>
      <inertia ixx="0.002041166666666667" ixy="0.0" ixz="0.0" iyy="0.002041166666666667" iyz="0.0" izz="0.003249"/>
    </inertial>
  </link>
  <joint name="mid_r_wheel_joint" type="continuous">
    <parent link="chassis"/>
    <child link="mid_r_wheel"/>
    <origin rpy="1.5707963267948966 0 0" xyz="0.18 -0.4 -0.35"/>
    <axis xyz="0 0 1"/>
  </joint>
  <link name="back_l_wheel">
    <visual>
      <geometry>
        <cylinder length="0.1" radius="0.114"/>
      </geometry>
      <material name="Grey">
        <color rgba="0.7 0.7 0.7 1.0"/>
      </material>
    </visual>
    <collision>
      <geometry>
        <cylinder length="0.1" radius="0.114"/>
      </geometry>
    </collision>
    <inertial>
      <mass value="0.5"/>
      <inertia ixx="0.002041166666666667" ixy="0.0" ixz="0.0" iyy="0.002041166666666667" iyz="0.0" izz="0.003249"/>
    </inertial>
  </link>
  <joint name="back_l_wheel_joint" type="continuous">
    <parent link="chassis"/>
    <child link="back_l_wheel"/>
    <origin rpy="1.5707963267948966 0 0" xyz="-0.22000000000000003 0.4 -0.35"/>
    <axis xyz="0 0 1"/>
  </joint>
  <link name="back_r_wheel">
    <visual>
      <geometry>
        <cylinder length="0.1" radius="0.114"/>
      </geometry>
      <material name="Grey">
        <color rgba="0.7 0.7 0.7 1.0"/>
      </material>
    </visual>
    <collision>
      <geometry>
        <cylinder length="0.1" radius="0.114"/>
      </geometry>
    </collision>
    <inertial>
      <mass value="0.5"/>
      <inertia ixx="0.002041166666666667" ixy="0.0" ixz="0.0" iyy="0.002041166666666667" iyz="0.0" izz="0.003249"/>
    </inertial>
  </link>
  <joint name="back_r_wheel_joint" type="continuous">
    <parent link="chassis"/>
    <child link="back_r_wheel"/>
    <origin rpy="1.5707963267948966 0 0" xyz="-0.22000000000000003 -0.4 -0.35"/>
    <axis xyz="0 0 1"/>
  </joint>
  <!-- Joints -->
  <!-- Robot Footprint -->
  <link name="base_footprint"/>
  <joint name="base_joint" type="fixed">
    <parent link="base_link"/>
    <child link="base_footprint"/>
    <origin rpy="0 0 0" xyz="0.0 0.0 -0.44999999999999996"/>
  </joint>
</robot>
