<?xml version="1.0" ?>
<!-- =================================================================================== -->
<!-- |    This document was autogenerated by xacro from /home/ethan/Robotics/Rover/src/uirover_description/urdf/uirover.urdf.xacro | -->
<!-- |    EDITING THIS FILE BY HAND IS NOT RECOMMENDED                                 | -->
<!-- =================================================================================== -->
<robot name="uirover">
  <!-- BASE LINK -->
  <link name="base_link"/>
  <!-- CHASSIS -->
  <link name="chassis">
    <visual>
      <origin rpy="1.5707963267948966 0.0 0.0" xyz="0.0 0.203 0.0"/>
      <geometry>
        <mesh filename="file:///home/ethan/Robotics/Rover/build/uirover_description/ament_cmake_index/share/uirover_description/dae/chassis.dae"/>
      </geometry>
    </visual>
  </link>
  <joint name="chassis_joint" type="fixed">
    <parent link="base_link"/>
    <child link="chassis"/>
    <origin rpy="0 0 0" xyz="0 0 0"/>
  </joint>
  <!--L SUSPENSIONS-->
  <link name="l_suspension">
    <visual>
      <origin rpy="1.5707963267948966 0.0 3.141592653589793" xyz="0.085 0.02 -0.06"/>
      <geometry>
        <mesh filename="file:///home/ethan/Robotics/Rover/build/uirover_description/ament_cmake_index/share/uirover_description/dae/suspension.dae"/>
      </geometry>
    </visual>
  </link>
  <joint name="l_suspension_joint" type="fixed">
    <parent link="chassis"/>
    <child link="l_suspension"/>
    <origin rpy="0 0 0" xyz="0.35 0.28 0.1"/>
  </joint>
  <!--R SUSPENSIONS-->
  <link name="r_suspension">
    <visual>
      <origin rpy="1.5707963267948966 0.0 3.141592653589793" xyz="0.085 0.02 -0.06"/>
      <geometry>
        <mesh filename="file:///home/ethan/Robotics/Rover/build/uirover_description/ament_cmake_index/share/uirover_description/dae/suspension.dae"/>
      </geometry>
    </visual>
  </link>
  <joint name="r_suspension_joint" type="fixed">
    <parent link="chassis"/>
    <child link="r_suspension"/>
    <origin rpy="0 0 0" xyz="0.35 -0.28 0.1"/>
  </joint>
  <link name=" ">
    <visual>
      <origin rpy="0 1.5707963267948966 0" xyz="0 0 -0.08"/>
      <geometry>
        <mesh filename="file:///home/ethan/Robotics/Rover/build/uirover_description/ament_cmake_index/share/uirover_description/dae/wheel.dae"/>
      </geometry>
    </visual>
    <collision>
      <geometry>
        <cylinder length="0.1" radius="0.114"/>
      </geometry>
    </collision>
    <inertial>
      <mass value="0.5"/>
      <inertia ixx="0.002041166666666667" ixy="0.0" ixz="0.0" iyy="0.002041166666666667" iyz="0.0" izz="0.003249"/>
    </inertial>
  </link>
  <joint name=" _joint" type="continuous">
    <parent link="l_suspension"/>
    <child link=" "/>
    <origin rpy="-1.5707963267948966 0 0" xyz="0.436 0.1 -0.342"/>
    <axis xyz="0 0 1"/>
  </joint>
  <link name="fr_wheel">
    <visual>
      <origin rpy="0 -1.5707963267948966 0" xyz="0 0 0.08"/>
      <geometry>
        <mesh filename="file:///home/ethan/Robotics/Rover/build/uirover_description/ament_cmake_index/share/uirover_description/dae/wheel.dae"/>
      </geometry>
    </visual>
    <collision>
      <geometry>
        <cylinder length="0.1" radius="0.114"/>
      </geometry>
    </collision>
    <inertial>
      <mass value="0.5"/>
      <inertia ixx="0.002041166666666667" ixy="0.0" ixz="0.0" iyy="0.002041166666666667" iyz="0.0" izz="0.003249"/>
    </inertial>
  </link>
  <joint name="fr_wheel_joint" type="continuous">
    <parent link="r_suspension"/>
    <child link="fr_wheel"/>
    <origin rpy="-1.5707963267948966 0 0" xyz="0.436 -0.1 -0.342"/>
    <axis xyz="0 0 1"/>
  </joint>
  <link name="ml_wheel">
    <visual>
      <origin rpy="0 1.5707963267948966 0" xyz="0 0 -0.08"/>
      <geometry>
        <mesh filename="file:///home/ethan/Robotics/Rover/build/uirover_description/ament_cmake_index/share/uirover_description/dae/wheel.dae"/>
      </geometry>
    </visual>
    <collision>
      <geometry>
        <cylinder length="0.1" radius="0.114"/>
      </geometry>
    </collision>
    <inertial>
      <mass value="0.5"/>
      <inertia ixx="0.002041166666666667" ixy="0.0" ixz="0.0" iyy="0.002041166666666667" iyz="0.0" izz="0.003249"/>
    </inertial>
  </link>
  <joint name="ml_wheel_joint" type="continuous">
    <parent link="l_suspension"/>
    <child link="ml_wheel"/>
    <origin rpy="-1.5707963267948966 0 0" xyz="0.016 0.1 -0.342"/>
    <axis xyz="0 0 1"/>
  </joint>
  <link name="mr_wheel">
    <visual>
      <origin rpy="0 -1.5707963267948966 0" xyz="0 0 0.08"/>
      <geometry>
        <mesh filename="file:///home/ethan/Robotics/Rover/build/uirover_description/ament_cmake_index/share/uirover_description/dae/wheel.dae"/>
      </geometry>
    </visual>
    <collision>
      <geometry>
        <cylinder length="0.1" radius="0.114"/>
      </geometry>
    </collision>
    <inertial>
      <mass value="0.5"/>
      <inertia ixx="0.002041166666666667" ixy="0.0" ixz="0.0" iyy="0.002041166666666667" iyz="0.0" izz="0.003249"/>
    </inertial>
  </link>
  <joint name="mr_wheel_joint" type="continuous">
    <parent link="r_suspension"/>
    <child link="mr_wheel"/>
    <origin rpy="-1.5707963267948966 0 0" xyz="0.016 -0.1 -0.342"/>
    <axis xyz="0 0 1"/>
  </joint>
  <link name="bl_wheel">
    <visual>
      <origin rpy="0 1.5707963267948966 0" xyz="0 0 -0.08"/>
      <geometry>
        <mesh filename="file:///home/ethan/Robotics/Rover/build/uirover_description/ament_cmake_index/share/uirover_description/dae/wheel.dae"/>
      </geometry>
    </visual>
    <collision>
      <geometry>
        <cylinder length="0.1" radius="0.114"/>
      </geometry>
    </collision>
    <inertial>
      <mass value="0.5"/>
      <inertia ixx="0.002041166666666667" ixy="0.0" ixz="0.0" iyy="0.002041166666666667" iyz="0.0" izz="0.003249"/>
    </inertial>
  </link>
  <joint name="bl_wheel_joint" type="continuous">
    <parent link="l_suspension"/>
    <child link="bl_wheel"/>
    <origin rpy="-1.5707963267948966 0 0" xyz="-0.434 0.1 -0.342"/>
    <axis xyz="0 0 1"/>
  </joint>
  <link name="br_wheel">
    <visual>
      <origin rpy="0 -1.5707963267948966 0" xyz="0 0 0.08"/>
      <geometry>
        <mesh filename="file:///home/ethan/Robotics/Rover/build/uirover_description/ament_cmake_index/share/uirover_description/dae/wheel.dae"/>
      </geometry>
    </visual>
    <collision>
      <geometry>
        <cylinder length="0.1" radius="0.114"/>
      </geometry>
    </collision>
    <inertial>
      <mass value="0.5"/>
      <inertia ixx="0.002041166666666667" ixy="0.0" ixz="0.0" iyy="0.002041166666666667" iyz="0.0" izz="0.003249"/>
    </inertial>
  </link>
  <joint name="br_wheel_joint" type="continuous">
    <parent link="r_suspension"/>
    <child link="br_wheel"/>
    <origin rpy="-1.5707963267948966 0 0" xyz="-0.434 -0.1 -0.342"/>
    <axis xyz="0 0 1"/>
  </joint>
  <!-- Robot Footprint -->
  <!-- This is needed for nav libraries. Its the 2D top-down profile of the robot. Makes for simpler collision detection. -->
  <link name="base_footprint"/>
  <joint name="base_footprint_joint" type="fixed">
    <parent link="base_link"/>
    <child link="base_footprint"/>
    <origin rpy="0 0 0" xyz="0.0 0.0 -0.44999999999999996"/>
  </joint>
  <!-- placeholder for ros2 control -->
  <!-- https://github.com/ros-controls/ros2_control_demos/blob/master/example_9/ -->
  <!-- https://control.ros.org/rolling/doc/getting_started/getting_started.html -->
  <!-- https://control.ros.org/rolling/doc/gz_ros2_control/doc/index.html -->
  <ros2_control name="uirover_control" type="system">
    <hardware>
      <!-- <xacro:unless value="${use_gazebo}">
                    <plugin>uirover_hardware/RRBotSystemPositionOnlyHardware</plugin>
                    <param name="example_param_hw_start_duration_sec">0</param>
                    <param name="example_param_hw_stop_duration_sec">3.0</param>
                    <param name="example_param_hw_slowdown">100</param>
                </xacro:unless> -->
    </hardware>
  </ros2_control>
  <!-- =============================== -->
  <!--            SENSORS              -->
  <!-- =============================== -->
  <link name="demo_camera">
    <visual>
      <origin rpy="0.0 1.5707963267948966 0.0" xyz="0.0 0.0 0.0"/>
      <geometry>
        <cylinder length="0.01" radius="0.01"/>
      </geometry>
      <material name="Grey">
        <color rgba="0.7 0.7 0.7 1.0"/>
      </material>
    </visual>
    <visual>
      <origin rpy="0.0 0.0 0.0" xyz="-0.005 0.0 0.0"/>
      <geometry>
        <box size="0.005 0.03 0.03"/>
      </geometry>
    </visual>
    <collision>
      <geometry>
        <cylinder length="0.01" radius="0.01"/>
      </geometry>
    </collision>
    <inertial>
      <mass value="0.1"/>
      <inertia ixx="3.333333333333333e-06" ixy="0.0" ixz="0.0" iyy="3.333333333333333e-06" iyz="0.0" izz="5e-06"/>
    </inertial>
  </link>
  <gazebo reference="demo_camera">
    <sensor name="boundingbox_camera" type="boundingbox_camera">
      <topic>demo_camera</topic>
      <camera>
        <box_type>2d</box_type>
        <!-- 110 deg FOV -->
        <horizontal_fov>1.9198</horizontal_fov>
        <image>
          <width>800</width>
          <height>600</height>
        </image>
        <clip>
          <near>0.1</near>
          <far>10</far>
        </clip>
      </camera>
      <always_on>1</always_on>
      <update_rate>30</update_rate>
      <visualize>true</visualize>
    </sensor>
  </gazebo>
  <joint name="front_camera_joint" type="fixed">
    <origin rpy="0.0 0.5 0.0" xyz="0.0 0.2 0.8"/>
    <parent link="base_link"/>
    <child link="demo_camera"/>
  </joint>
</robot>
