<?xml version="1.0" ?>
<!-- =================================================================================== -->
<!-- |    This document was autogenerated by xacro from /home/ethan-holter/Projects/Rover/src/uirover_description/urdf/uirover.urdf.xacro | -->
<!-- |    EDITING THIS FILE BY HAND IS NOT RECOMMENDED                                 | -->
<!-- =================================================================================== -->
<robot name="uirover">
  <!-- BASE LINK -->
  <link name="base_link"/>
  <link name="chassis">
    <visual>
      <geometry>
        <box size="0.45 0.45 0.3"/>
      </geometry>
      <material name="Grey">
        <color rgba="0.7 0.7 0.7 1.0"/>
      </material>
    </visual>
    <collision>
      <geometry>
        <box size="0.45 0.45 0.3"/>
      </geometry>
    </collision>
    <inertial>
      <mass value="5"/>
      <inertia ixx="0.12187499999999998" ixy="0.0" ixz="0.0" iyy="0.12187499999999998" iyz="0.0" izz="0.16874999999999998"/>
    </inertial>
  </link>
  <inertial>
    <mass value="5"/>
    <inertia ixx="0.12187499999999998" ixy="0.0" ixz="0.0" iyy="0.12187499999999998" iyz="0.0" izz="0.16874999999999998"/>
  </inertial>
  <joint name="chassis_joint" type="fixed">
    <parent link="base_link"/>
    <child link="chassis"/>
    <origin rpy="0 0 0" xyz="0 0 0"/>
  </joint>
  <link name="arm_platform">
    <visual>
      <geometry>
        <box size="0.3 0.45 0.05"/>
      </geometry>
      <material name="Grey">
        <color rgba="0.7 0.7 0.7 1.0"/>
      </material>
    </visual>
    <collision>
      <geometry>
        <box size="0.3 0.45 0.05"/>
      </geometry>
    </collision>
    <inertial>
      <mass value="3"/>
      <inertia ixx="0.051250000000000004" ixy="0.0" ixz="0.0" iyy="0.023125" iyz="0.0" izz="0.073125"/>
    </inertial>
  </link>
  <joint name="arm_platform_joint" type="fixed">
    <parent link="base_link"/>
    <child link="arm_platform"/>
    <origin rpy="0 0 0" xyz="0.375 0 -0.125"/>
  </joint>
  <link name="fl_swivel">
    <visual>
      <geometry>
        <sphere radius="0.05"/>
      </geometry>
      <material name="Grey">
        <color rgba="0.7 0.7 0.7 1.0"/>
      </material>
    </visual>
    <collision>
      <geometry>
        <sphere radius="0.05"/>
      </geometry>
    </collision>
    <inertial>
      <mass value="0.1"/>
      <inertia ixx="0.0001666666666666667" ixy="0.0" ixz="0.0" iyy="0.0001666666666666667" iyz="0.0" izz="0.0001666666666666667"/>
    </inertial>
  </link>
  <joint name="fl_swivel_joint" type="revolute">
    <parent link="base_link"/>
    <child link="fl_swivel"/>
    <origin rpy="0 0 0" xyz="0.5800000000000001 0.4 -0.35"/>
    <axis xyz="0 0 1"/>
    <limit effort="10" lower="-1.5707963267948966" upper="1.5707963267948966" velocity="1"/>
  </joint>
  <link name="fr_swivel">
    <visual>
      <geometry>
        <sphere radius="0.05"/>
      </geometry>
      <material name="Grey">
        <color rgba="0.7 0.7 0.7 1.0"/>
      </material>
    </visual>
    <collision>
      <geometry>
        <sphere radius="0.05"/>
      </geometry>
    </collision>
    <inertial>
      <mass value="0.1"/>
      <inertia ixx="0.0001666666666666667" ixy="0.0" ixz="0.0" iyy="0.0001666666666666667" iyz="0.0" izz="0.0001666666666666667"/>
    </inertial>
  </link>
  <joint name="fr_swivel_joint" type="revolute">
    <parent link="base_link"/>
    <child link="fr_swivel"/>
    <origin rpy="0 0 0" xyz="0.5800000000000001 -0.4 -0.35"/>
    <axis xyz="0 0 1"/>
    <limit effort="10" lower="-1.5707963267948966" upper="1.5707963267948966" velocity="1"/>
  </joint>
  <link name="bl_swivel">
    <visual>
      <geometry>
        <sphere radius="0.05"/>
      </geometry>
      <material name="Grey">
        <color rgba="0.7 0.7 0.7 1.0"/>
      </material>
    </visual>
    <collision>
      <geometry>
        <sphere radius="0.05"/>
      </geometry>
    </collision>
    <inertial>
      <mass value="0.1"/>
      <inertia ixx="0.0001666666666666667" ixy="0.0" ixz="0.0" iyy="0.0001666666666666667" iyz="0.0" izz="0.0001666666666666667"/>
    </inertial>
  </link>
  <joint name="bl_swivel_joint" type="revolute">
    <parent link="base_link"/>
    <child link="bl_swivel"/>
    <origin rpy="0 0 0" xyz="-0.22000000000000003 0.4 -0.35"/>
    <axis xyz="0 0 1"/>
    <limit effort="10" lower="-1.5707963267948966" upper="1.5707963267948966" velocity="1"/>
  </joint>
  <link name="br_swivel">
    <visual>
      <geometry>
        <sphere radius="0.05"/>
      </geometry>
      <material name="Grey">
        <color rgba="0.7 0.7 0.7 1.0"/>
      </material>
    </visual>
    <collision>
      <geometry>
        <sphere radius="0.05"/>
      </geometry>
    </collision>
    <inertial>
      <mass value="0.1"/>
      <inertia ixx="0.0001666666666666667" ixy="0.0" ixz="0.0" iyy="0.0001666666666666667" iyz="0.0" izz="0.0001666666666666667"/>
    </inertial>
  </link>
  <joint name="br_swivel_joint" type="revolute">
    <parent link="base_link"/>
    <child link="br_swivel"/>
    <origin rpy="0 0 0" xyz="-0.22000000000000003 -0.4 -0.35"/>
    <axis xyz="0 0 1"/>
    <limit effort="10" lower="-1.5707963267948966" upper="1.5707963267948966" velocity="1"/>
  </joint>
  <link name="fl_wheel">
    <visual>
      <geometry>
        <cylinder length="0.1" radius="0.114"/>
      </geometry>
      <material name="Grey">
        <color rgba="0.7 0.7 0.7 1.0"/>
      </material>
    </visual>
    <collision>
      <geometry>
        <cylinder length="0.1" radius="0.114"/>
      </geometry>
    </collision>
    <inertial>
      <mass value="0.5"/>
      <inertia ixx="0.002041166666666667" ixy="0.0" ixz="0.0" iyy="0.002041166666666667" iyz="0.0" izz="0.003249"/>
    </inertial>
  </link>
  <joint name="fl_wheel_joint" type="continuous">
    <parent link="fl_swivel"/>
    <child link="fl_wheel"/>
    <origin rpy="-1.5707963267948966 0 0" xyz="0 0 0"/>
    <axis xyz="0 0 1"/>
  </joint>
  <link name="fr_wheel">
    <visual>
      <geometry>
        <cylinder length="0.1" radius="0.114"/>
      </geometry>
      <material name="Grey">
        <color rgba="0.7 0.7 0.7 1.0"/>
      </material>
    </visual>
    <collision>
      <geometry>
        <cylinder length="0.1" radius="0.114"/>
      </geometry>
    </collision>
    <inertial>
      <mass value="0.5"/>
      <inertia ixx="0.002041166666666667" ixy="0.0" ixz="0.0" iyy="0.002041166666666667" iyz="0.0" izz="0.003249"/>
    </inertial>
  </link>
  <joint name="fr_wheel_joint" type="continuous">
    <parent link="fr_swivel"/>
    <child link="fr_wheel"/>
    <origin rpy="-1.5707963267948966 0 0" xyz="0 0 0"/>
    <axis xyz="0 0 1"/>
  </joint>
  <link name="ml_wheel">
    <visual>
      <geometry>
        <cylinder length="0.1" radius="0.114"/>
      </geometry>
      <material name="Grey">
        <color rgba="0.7 0.7 0.7 1.0"/>
      </material>
    </visual>
    <collision>
      <geometry>
        <cylinder length="0.1" radius="0.114"/>
      </geometry>
    </collision>
    <inertial>
      <mass value="0.5"/>
      <inertia ixx="0.002041166666666667" ixy="0.0" ixz="0.0" iyy="0.002041166666666667" iyz="0.0" izz="0.003249"/>
    </inertial>
  </link>
  <joint name="ml_wheel_joint" type="continuous">
    <parent link="chassis"/>
    <child link="ml_wheel"/>
    <origin rpy="-1.5707963267948966 0 0" xyz="0.18 0.4 -0.35"/>
    <axis xyz="0 0 1"/>
  </joint>
  <link name="mr_wheel">
    <visual>
      <geometry>
        <cylinder length="0.1" radius="0.114"/>
      </geometry>
      <material name="Grey">
        <color rgba="0.7 0.7 0.7 1.0"/>
      </material>
    </visual>
    <collision>
      <geometry>
        <cylinder length="0.1" radius="0.114"/>
      </geometry>
    </collision>
    <inertial>
      <mass value="0.5"/>
      <inertia ixx="0.002041166666666667" ixy="0.0" ixz="0.0" iyy="0.002041166666666667" iyz="0.0" izz="0.003249"/>
    </inertial>
  </link>
  <joint name="mr_wheel_joint" type="continuous">
    <parent link="chassis"/>
    <child link="mr_wheel"/>
    <origin rpy="-1.5707963267948966 0 0" xyz="0.18 -0.4 -0.35"/>
    <axis xyz="0 0 1"/>
  </joint>
  <link name="bl_wheel">
    <visual>
      <geometry>
        <cylinder length="0.1" radius="0.114"/>
      </geometry>
      <material name="Grey">
        <color rgba="0.7 0.7 0.7 1.0"/>
      </material>
    </visual>
    <collision>
      <geometry>
        <cylinder length="0.1" radius="0.114"/>
      </geometry>
    </collision>
    <inertial>
      <mass value="0.5"/>
      <inertia ixx="0.002041166666666667" ixy="0.0" ixz="0.0" iyy="0.002041166666666667" iyz="0.0" izz="0.003249"/>
    </inertial>
  </link>
  <joint name="bl_wheel_joint" type="continuous">
    <parent link="bl_swivel"/>
    <child link="bl_wheel"/>
    <origin rpy="-1.5707963267948966 0 0" xyz="0 0 0"/>
    <axis xyz="0 0 1"/>
  </joint>
  <link name="br_wheel">
    <visual>
      <geometry>
        <cylinder length="0.1" radius="0.114"/>
      </geometry>
      <material name="Grey">
        <color rgba="0.7 0.7 0.7 1.0"/>
      </material>
    </visual>
    <collision>
      <geometry>
        <cylinder length="0.1" radius="0.114"/>
      </geometry>
    </collision>
    <inertial>
      <mass value="0.5"/>
      <inertia ixx="0.002041166666666667" ixy="0.0" ixz="0.0" iyy="0.002041166666666667" iyz="0.0" izz="0.003249"/>
    </inertial>
  </link>
  <joint name="br_wheel_joint" type="continuous">
    <parent link="br_swivel"/>
    <child link="br_wheel"/>
    <origin rpy="-1.5707963267948966 0 0" xyz="0 0 0"/>
    <axis xyz="0 0 1"/>
  </joint>
  <!-- Robot Footprint -->
  <!-- This is needed for nav libraries. Its the 2D top-down profile of the robot. Makes for simpler collision detection. -->
  <link name="base_footprint"/>
  <joint name="base_footprint_joint" type="fixed">
    <parent link="base_link"/>
    <child link="base_footprint"/>
    <origin rpy="0 0 0" xyz="0.0 0.0 -0.44999999999999996"/>
  </joint>
  <!-- placeholder for ros2 control -->
  <!-- https://github.com/ros-controls/ros2_control_demos/blob/master/example_9/ -->
  <!-- https://control.ros.org/rolling/doc/getting_started/getting_started.html -->
  <!-- https://control.ros.org/rolling/doc/gz_ros2_control/doc/index.html -->
  <ros2_control name="uirover_control" type="system">
    <hardware>
      <!-- <xacro:unless value="${use_gazebo}">
                    <plugin>uirover_hardware/RRBotSystemPositionOnlyHardware</plugin>
                    <param name="example_param_hw_start_duration_sec">0</param>
                    <param name="example_param_hw_stop_duration_sec">3.0</param>
                    <param name="example_param_hw_slowdown">100</param>
                </xacro:unless> -->
    </hardware>
  </ros2_control>
  <!-- =============================== -->
  <!--            SENSORS              -->
  <!-- =============================== -->
  <link name="demo_camera">
    <visual>
      <geometry>
        <cylinder length="0.01" radius="0.01"/>
      </geometry>
      <material name="Grey">
        <color rgba="0.7 0.7 0.7 1.0"/>
      </material>
    </visual>
    <collision>
      <geometry>
        <cylinder length="0.01" radius="0.01"/>
      </geometry>
    </collision>
    <inertial>
      <mass value="0.1"/>
      <inertia ixx="3.333333333333333e-06" ixy="0.0" ixz="0.0" iyy="3.333333333333333e-06" iyz="0.0" izz="5e-06"/>
    </inertial>
  </link>
  <gazebo reference="demo_camera">
    <sensor name="boundingbox_camera" type="boundingbox_camera">
      <topic>boxes</topic>
      <camera>
        <box_type>2d</box_type>
        <horizontal_fov>1.047</horizontal_fov>
        <image>
          <width>800</width>
          <height>600</height>
        </image>
        <clip>
          <near>0.1</near>
          <far>10</far>
        </clip>
      </camera>
      <always_on>1</always_on>
      <update_rate>30</update_rate>
      <visualize>true</visualize>
    </sensor>
  </gazebo>
  <joint name="front_camera_joint" type="fixed">
    <origin rpy="0.0 0.0 0.0" xyz="1.0 0.0 0.0"/>
    <parent link="base_link"/>
    <child link="demo_camera"/>
  </joint>
</robot>
